[2019-10-27 14:45:48 +0530] [40268] [DEBUG] Current configuration:
  config: None
  bind: ['localhost:5000']
  backlog: 2048
  workers: 4
  worker_class: gevent
  threads: 1
  worker_connections: 1000
  max_requests: 0
  max_requests_jitter: 0
  timeout: 600
  graceful_timeout: 30
  keepalive: 2
  limit_request_line: 4094
  limit_request_fields: 100
  limit_request_field_size: 8190
  reload: True
  reload_engine: auto
  reload_extra_files: []
  spew: False
  check_config: False
  preload_app: False
  sendfile: None
  reuse_port: False
  chdir: /Users/niksharm/Downloads/sampleproject-master/digits_sequence_generator
  daemon: False
  raw_env: []
  pidfile: None
  worker_tmp_dir: None
  user: 1528380487
  group: 1493692218
  umask: 0
  initgroups: False
  tmp_upload_dir: None
  secure_scheme_headers: {'X-FORWARDED-PROTOCOL': 'ssl', 'X-FORWARDED-PROTO': 'https', 'X-FORWARDED-SSL': 'on'}
  forwarded_allow_ips: ['127.0.0.1']
  accesslog: config/gunicorn-digit-logs.log
  disable_redirect_access_to_syslog: False
  access_log_format: %(h)s %(l)s %(u)s %(t)s "%(r)s" %(s)s %(b)s "%(f)s" "%(a)s"
  errorlog: config/gunicorn-logs.log
  loglevel: DEBUG
  capture_output: False
  logger_class: gunicorn.glogging.Logger
  logconfig: None
  logconfig_dict: {}
  syslog_addr: unix:///var/run/syslog
  syslog: False
  syslog_prefix: None
  syslog_facility: user
  enable_stdio_inheritance: False
  statsd_host: None
  statsd_prefix: 
  proc_name: None
  default_proc_name: api_controller:app
  pythonpath: None
  paste: None
  on_starting: <function OnStarting.on_starting at 0x1025ea2f0>
  on_reload: <function OnReload.on_reload at 0x1025ea400>
  when_ready: <function WhenReady.when_ready at 0x1025ea510>
  pre_fork: <function Prefork.pre_fork at 0x1025ea620>
  post_fork: <function Postfork.post_fork at 0x1025ea730>
  post_worker_init: <function PostWorkerInit.post_worker_init at 0x1025ea840>
  worker_int: <function WorkerInt.worker_int at 0x1025ea950>
  worker_abort: <function WorkerAbort.worker_abort at 0x1025eaa60>
  pre_exec: <function PreExec.pre_exec at 0x1025eab70>
  pre_request: <function PreRequest.pre_request at 0x1025eac80>
  post_request: <function PostRequest.post_request at 0x1025ead08>
  child_exit: <function ChildExit.child_exit at 0x1025eae18>
  worker_exit: <function WorkerExit.worker_exit at 0x1025eaf28>
  nworkers_changed: <function NumWorkersChanged.nworkers_changed at 0x1026050d0>
  on_exit: <function OnExit.on_exit at 0x1026051e0>
  proxy_protocol: False
  proxy_allow_ips: ['127.0.0.1']
  keyfile: None
  certfile: None
  ssl_version: 2
  cert_reqs: 0
  ca_certs: None
  suppress_ragged_eofs: True
  do_handshake_on_connect: False
  ciphers: TLSv1
  raw_paste_global_conf: []
[2019-10-27 14:45:48 +0530] [40268] [INFO] Starting gunicorn 19.9.0
[2019-10-27 14:45:48 +0530] [40268] [DEBUG] Arbiter booted
[2019-10-27 14:45:48 +0530] [40268] [INFO] Listening at: http://127.0.0.1:5000 (40268)
[2019-10-27 14:45:48 +0530] [40268] [INFO] Using worker: gevent
[2019-10-27 14:45:48 +0530] [40273] [INFO] Booting worker with pid: 40273
[2019-10-27 14:45:48 +0530] [40274] [INFO] Booting worker with pid: 40274
[2019-10-27 14:45:48 +0530] [40275] [INFO] Booting worker with pid: 40275
[2019-10-27 14:45:48 +0530] [40276] [INFO] Booting worker with pid: 40276
[2019-10-27 14:45:48 +0530] [40268] [DEBUG] 4 workers
[2019-10-27 14:45:49 +0530] [40274] [ERROR] Exception in worker process
Traceback (most recent call last):
  File "/Users/niksharm/.virtualenvs/env1/lib/python3.6/site-packages/gunicorn/arbiter.py", line 583, in spawn_worker
    worker.init_process()
  File "/Users/niksharm/.virtualenvs/env1/lib/python3.6/site-packages/gunicorn/workers/ggevent.py", line 203, in init_process
    super(GeventWorker, self).init_process()
  File "/Users/niksharm/.virtualenvs/env1/lib/python3.6/site-packages/gunicorn/workers/base.py", line 129, in init_process
    self.load_wsgi()
  File "/Users/niksharm/.virtualenvs/env1/lib/python3.6/site-packages/gunicorn/workers/base.py", line 138, in load_wsgi
    self.wsgi = self.app.wsgi()
  File "/Users/niksharm/.virtualenvs/env1/lib/python3.6/site-packages/gunicorn/app/base.py", line 67, in wsgi
    self.callable = self.load()
  File "/Users/niksharm/.virtualenvs/env1/lib/python3.6/site-packages/gunicorn/app/wsgiapp.py", line 52, in load
    return self.load_wsgiapp()
  File "/Users/niksharm/.virtualenvs/env1/lib/python3.6/site-packages/gunicorn/app/wsgiapp.py", line 41, in load_wsgiapp
    return util.import_app(self.app_uri)
  File "/Users/niksharm/.virtualenvs/env1/lib/python3.6/site-packages/gunicorn/util.py", line 350, in import_app
    __import__(module)
  File "/Users/niksharm/Downloads/sampleproject-master/digits_sequence_generator/api_controller.py", line 3, in <module>
    from digits_sequence_generator import generator
  File "/Users/niksharm/.virtualenvs/env1/lib/python3.6/site-packages/digits_sequence_generator/generator/__init__.py", line 4, in <module>
    from digits_sequence_generator.generator import image_generator
  File "/Users/niksharm/.virtualenvs/env1/lib/python3.6/site-packages/digits_sequence_generator/generator/image_generator.py", line 6, in <module>
    from digits_sequence_generator.data_handler import post_processing
  File "/Users/niksharm/.virtualenvs/env1/lib/python3.6/site-packages/digits_sequence_generator/data_handler/post_processing.py", line 11, in <module>
    config = utility.read_config()
  File "/Users/niksharm/.virtualenvs/env1/lib/python3.6/site-packages/digits_sequence_generator/generator/util.py", line 10, in read_config
    with open(os.path.join(config_folder_path,"config/config.yml"), 'r') as ymlfile:
FileNotFoundError: [Errno 2] No such file or directory: '/Users/niksharm/.virtualenvs/env1/lib/python3.6/site-packages/digits_sequence_generator/generator/../config/config.yml'
[2019-10-27 14:45:49 +0530] [40273] [ERROR] Exception in worker process
Traceback (most recent call last):
  File "/Users/niksharm/.virtualenvs/env1/lib/python3.6/site-packages/gunicorn/arbiter.py", line 583, in spawn_worker
    worker.init_process()
  File "/Users/niksharm/.virtualenvs/env1/lib/python3.6/site-packages/gunicorn/workers/ggevent.py", line 203, in init_process
    super(GeventWorker, self).init_process()
  File "/Users/niksharm/.virtualenvs/env1/lib/python3.6/site-packages/gunicorn/workers/base.py", line 129, in init_process
    self.load_wsgi()
  File "/Users/niksharm/.virtualenvs/env1/lib/python3.6/site-packages/gunicorn/workers/base.py", line 138, in load_wsgi
    self.wsgi = self.app.wsgi()
  File "/Users/niksharm/.virtualenvs/env1/lib/python3.6/site-packages/gunicorn/app/base.py", line 67, in wsgi
    self.callable = self.load()
  File "/Users/niksharm/.virtualenvs/env1/lib/python3.6/site-packages/gunicorn/app/wsgiapp.py", line 52, in load
    return self.load_wsgiapp()
  File "/Users/niksharm/.virtualenvs/env1/lib/python3.6/site-packages/gunicorn/app/wsgiapp.py", line 41, in load_wsgiapp
    return util.import_app(self.app_uri)
  File "/Users/niksharm/.virtualenvs/env1/lib/python3.6/site-packages/gunicorn/util.py", line 350, in import_app
    __import__(module)
  File "/Users/niksharm/Downloads/sampleproject-master/digits_sequence_generator/api_controller.py", line 3, in <module>
    from digits_sequence_generator import generator
  File "/Users/niksharm/.virtualenvs/env1/lib/python3.6/site-packages/digits_sequence_generator/generator/__init__.py", line 4, in <module>
    from digits_sequence_generator.generator import image_generator
  File "/Users/niksharm/.virtualenvs/env1/lib/python3.6/site-packages/digits_sequence_generator/generator/image_generator.py", line 6, in <module>
    from digits_sequence_generator.data_handler import post_processing
  File "/Users/niksharm/.virtualenvs/env1/lib/python3.6/site-packages/digits_sequence_generator/data_handler/post_processing.py", line 11, in <module>
    config = utility.read_config()
  File "/Users/niksharm/.virtualenvs/env1/lib/python3.6/site-packages/digits_sequence_generator/generator/util.py", line 10, in read_config
    with open(os.path.join(config_folder_path,"config/config.yml"), 'r') as ymlfile:
FileNotFoundError: [Errno 2] No such file or directory: '/Users/niksharm/.virtualenvs/env1/lib/python3.6/site-packages/digits_sequence_generator/generator/../config/config.yml'
[2019-10-27 14:45:49 +0530] [40274] [INFO] Worker exiting (pid: 40274)
[2019-10-27 14:45:49 +0530] [40273] [INFO] Worker exiting (pid: 40273)
[2019-10-27 14:45:49 +0530] [40275] [ERROR] Exception in worker process
Traceback (most recent call last):
  File "/Users/niksharm/.virtualenvs/env1/lib/python3.6/site-packages/gunicorn/arbiter.py", line 583, in spawn_worker
    worker.init_process()
  File "/Users/niksharm/.virtualenvs/env1/lib/python3.6/site-packages/gunicorn/workers/ggevent.py", line 203, in init_process
    super(GeventWorker, self).init_process()
  File "/Users/niksharm/.virtualenvs/env1/lib/python3.6/site-packages/gunicorn/workers/base.py", line 129, in init_process
    self.load_wsgi()
  File "/Users/niksharm/.virtualenvs/env1/lib/python3.6/site-packages/gunicorn/workers/base.py", line 138, in load_wsgi
    self.wsgi = self.app.wsgi()
  File "/Users/niksharm/.virtualenvs/env1/lib/python3.6/site-packages/gunicorn/app/base.py", line 67, in wsgi
    self.callable = self.load()
  File "/Users/niksharm/.virtualenvs/env1/lib/python3.6/site-packages/gunicorn/app/wsgiapp.py", line 52, in load
    return self.load_wsgiapp()
  File "/Users/niksharm/.virtualenvs/env1/lib/python3.6/site-packages/gunicorn/app/wsgiapp.py", line 41, in load_wsgiapp
    return util.import_app(self.app_uri)
  File "/Users/niksharm/.virtualenvs/env1/lib/python3.6/site-packages/gunicorn/util.py", line 350, in import_app
    __import__(module)
  File "/Users/niksharm/Downloads/sampleproject-master/digits_sequence_generator/api_controller.py", line 3, in <module>
    from digits_sequence_generator import generator
  File "/Users/niksharm/.virtualenvs/env1/lib/python3.6/site-packages/digits_sequence_generator/generator/__init__.py", line 4, in <module>
    from digits_sequence_generator.generator import image_generator
  File "/Users/niksharm/.virtualenvs/env1/lib/python3.6/site-packages/digits_sequence_generator/generator/image_generator.py", line 6, in <module>
    from digits_sequence_generator.data_handler import post_processing
  File "/Users/niksharm/.virtualenvs/env1/lib/python3.6/site-packages/digits_sequence_generator/data_handler/post_processing.py", line 11, in <module>
    config = utility.read_config()
  File "/Users/niksharm/.virtualenvs/env1/lib/python3.6/site-packages/digits_sequence_generator/generator/util.py", line 10, in read_config
    with open(os.path.join(config_folder_path,"config/config.yml"), 'r') as ymlfile:
FileNotFoundError: [Errno 2] No such file or directory: '/Users/niksharm/.virtualenvs/env1/lib/python3.6/site-packages/digits_sequence_generator/generator/../config/config.yml'
[2019-10-27 14:45:49 +0530] [40275] [INFO] Worker exiting (pid: 40275)
[2019-10-27 14:45:49 +0530] [40276] [ERROR] Exception in worker process
Traceback (most recent call last):
  File "/Users/niksharm/.virtualenvs/env1/lib/python3.6/site-packages/gunicorn/arbiter.py", line 583, in spawn_worker
    worker.init_process()
  File "/Users/niksharm/.virtualenvs/env1/lib/python3.6/site-packages/gunicorn/workers/ggevent.py", line 203, in init_process
    super(GeventWorker, self).init_process()
  File "/Users/niksharm/.virtualenvs/env1/lib/python3.6/site-packages/gunicorn/workers/base.py", line 129, in init_process
    self.load_wsgi()
  File "/Users/niksharm/.virtualenvs/env1/lib/python3.6/site-packages/gunicorn/workers/base.py", line 138, in load_wsgi
    self.wsgi = self.app.wsgi()
  File "/Users/niksharm/.virtualenvs/env1/lib/python3.6/site-packages/gunicorn/app/base.py", line 67, in wsgi
    self.callable = self.load()
  File "/Users/niksharm/.virtualenvs/env1/lib/python3.6/site-packages/gunicorn/app/wsgiapp.py", line 52, in load
    return self.load_wsgiapp()
  File "/Users/niksharm/.virtualenvs/env1/lib/python3.6/site-packages/gunicorn/app/wsgiapp.py", line 41, in load_wsgiapp
    return util.import_app(self.app_uri)
  File "/Users/niksharm/.virtualenvs/env1/lib/python3.6/site-packages/gunicorn/util.py", line 350, in import_app
    __import__(module)
  File "/Users/niksharm/Downloads/sampleproject-master/digits_sequence_generator/api_controller.py", line 3, in <module>
    from digits_sequence_generator import generator
  File "/Users/niksharm/.virtualenvs/env1/lib/python3.6/site-packages/digits_sequence_generator/generator/__init__.py", line 4, in <module>
    from digits_sequence_generator.generator import image_generator
  File "/Users/niksharm/.virtualenvs/env1/lib/python3.6/site-packages/digits_sequence_generator/generator/image_generator.py", line 6, in <module>
    from digits_sequence_generator.data_handler import post_processing
  File "/Users/niksharm/.virtualenvs/env1/lib/python3.6/site-packages/digits_sequence_generator/data_handler/post_processing.py", line 11, in <module>
    config = utility.read_config()
  File "/Users/niksharm/.virtualenvs/env1/lib/python3.6/site-packages/digits_sequence_generator/generator/util.py", line 10, in read_config
    with open(os.path.join(config_folder_path,"config/config.yml"), 'r') as ymlfile:
FileNotFoundError: [Errno 2] No such file or directory: '/Users/niksharm/.virtualenvs/env1/lib/python3.6/site-packages/digits_sequence_generator/generator/../config/config.yml'
[2019-10-27 14:45:49 +0530] [40276] [INFO] Worker exiting (pid: 40276)
[2019-10-27 14:52:30 +0530] [40560] [DEBUG] Current configuration:
  config: None
  bind: ['localhost:5000']
  backlog: 2048
  workers: 4
  worker_class: gevent
  threads: 1
  worker_connections: 1000
  max_requests: 0
  max_requests_jitter: 0
  timeout: 600
  graceful_timeout: 30
  keepalive: 2
  limit_request_line: 4094
  limit_request_fields: 100
  limit_request_field_size: 8190
  reload: True
  reload_engine: auto
  reload_extra_files: []
  spew: False
  check_config: False
  preload_app: False
  sendfile: None
  reuse_port: False
  chdir: /Users/niksharm/Downloads/sampleproject-master/digits_sequence_generator
  daemon: False
  raw_env: []
  pidfile: None
  worker_tmp_dir: None
  user: 1528380487
  group: 1493692218
  umask: 0
  initgroups: False
  tmp_upload_dir: None
  secure_scheme_headers: {'X-FORWARDED-PROTOCOL': 'ssl', 'X-FORWARDED-PROTO': 'https', 'X-FORWARDED-SSL': 'on'}
  forwarded_allow_ips: ['127.0.0.1']
  accesslog: config/gunicorn-digit-logs.log
  disable_redirect_access_to_syslog: False
  access_log_format: %(h)s %(l)s %(u)s %(t)s "%(r)s" %(s)s %(b)s "%(f)s" "%(a)s"
  errorlog: config/gunicorn-logs.log
  loglevel: DEBUG
  capture_output: False
  logger_class: gunicorn.glogging.Logger
  logconfig: None
  logconfig_dict: {}
  syslog_addr: unix:///var/run/syslog
  syslog: False
  syslog_prefix: None
  syslog_facility: user
  enable_stdio_inheritance: False
  statsd_host: None
  statsd_prefix: 
  proc_name: None
  default_proc_name: api_controller:app
  pythonpath: None
  paste: None
  on_starting: <function OnStarting.on_starting at 0x1033ed2f0>
  on_reload: <function OnReload.on_reload at 0x1033ed400>
  when_ready: <function WhenReady.when_ready at 0x1033ed510>
  pre_fork: <function Prefork.pre_fork at 0x1033ed620>
  post_fork: <function Postfork.post_fork at 0x1033ed730>
  post_worker_init: <function PostWorkerInit.post_worker_init at 0x1033ed840>
  worker_int: <function WorkerInt.worker_int at 0x1033ed950>
  worker_abort: <function WorkerAbort.worker_abort at 0x1033eda60>
  pre_exec: <function PreExec.pre_exec at 0x1033edb70>
  pre_request: <function PreRequest.pre_request at 0x1033edc80>
  post_request: <function PostRequest.post_request at 0x1033edd08>
  child_exit: <function ChildExit.child_exit at 0x1033ede18>
  worker_exit: <function WorkerExit.worker_exit at 0x1033edf28>
  nworkers_changed: <function NumWorkersChanged.nworkers_changed at 0x1034080d0>
  on_exit: <function OnExit.on_exit at 0x1034081e0>
  proxy_protocol: False
  proxy_allow_ips: ['127.0.0.1']
  keyfile: None
  certfile: None
  ssl_version: 2
  cert_reqs: 0
  ca_certs: None
  suppress_ragged_eofs: True
  do_handshake_on_connect: False
  ciphers: TLSv1
  raw_paste_global_conf: []
[2019-10-27 14:52:30 +0530] [40560] [INFO] Starting gunicorn 19.9.0
[2019-10-27 14:52:30 +0530] [40560] [DEBUG] Arbiter booted
[2019-10-27 14:52:30 +0530] [40560] [INFO] Listening at: http://127.0.0.1:5000 (40560)
[2019-10-27 14:52:30 +0530] [40560] [INFO] Using worker: gevent
[2019-10-27 14:52:30 +0530] [40565] [INFO] Booting worker with pid: 40565
[2019-10-27 14:52:30 +0530] [40566] [INFO] Booting worker with pid: 40566
[2019-10-27 14:52:30 +0530] [40567] [INFO] Booting worker with pid: 40567
[2019-10-27 14:52:30 +0530] [40568] [INFO] Booting worker with pid: 40568
[2019-10-27 14:52:30 +0530] [40560] [DEBUG] 4 workers
[2019-10-27 14:52:31 +0530] [40566] [ERROR] Exception in worker process
Traceback (most recent call last):
  File "/Users/niksharm/.virtualenvs/env1/lib/python3.6/site-packages/gunicorn/arbiter.py", line 583, in spawn_worker
    worker.init_process()
  File "/Users/niksharm/.virtualenvs/env1/lib/python3.6/site-packages/gunicorn/workers/ggevent.py", line 203, in init_process
    super(GeventWorker, self).init_process()
  File "/Users/niksharm/.virtualenvs/env1/lib/python3.6/site-packages/gunicorn/workers/base.py", line 129, in init_process
    self.load_wsgi()
  File "/Users/niksharm/.virtualenvs/env1/lib/python3.6/site-packages/gunicorn/workers/base.py", line 138, in load_wsgi
    self.wsgi = self.app.wsgi()
  File "/Users/niksharm/.virtualenvs/env1/lib/python3.6/site-packages/gunicorn/app/base.py", line 67, in wsgi
    self.callable = self.load()
  File "/Users/niksharm/.virtualenvs/env1/lib/python3.6/site-packages/gunicorn/app/wsgiapp.py", line 52, in load
    return self.load_wsgiapp()
  File "/Users/niksharm/.virtualenvs/env1/lib/python3.6/site-packages/gunicorn/app/wsgiapp.py", line 41, in load_wsgiapp
    return util.import_app(self.app_uri)
  File "/Users/niksharm/.virtualenvs/env1/lib/python3.6/site-packages/gunicorn/util.py", line 350, in import_app
    __import__(module)
  File "/Users/niksharm/Downloads/sampleproject-master/digits_sequence_generator/api_controller.py", line 3, in <module>
    from digits_sequence_generator import generator
  File "/Users/niksharm/.virtualenvs/env1/lib/python3.6/site-packages/digits_sequence_generator/generator/__init__.py", line 4, in <module>
    from digits_sequence_generator.generator import image_generator
  File "/Users/niksharm/.virtualenvs/env1/lib/python3.6/site-packages/digits_sequence_generator/generator/image_generator.py", line 6, in <module>
    from digits_sequence_generator.data_handler import post_processing
  File "/Users/niksharm/.virtualenvs/env1/lib/python3.6/site-packages/digits_sequence_generator/data_handler/post_processing.py", line 11, in <module>
    config = utility.read_config()
  File "/Users/niksharm/.virtualenvs/env1/lib/python3.6/site-packages/digits_sequence_generator/generator/util.py", line 10, in read_config
    with open(os.path.join(config_folder_path,"config/config.yml"), 'r') as ymlfile:
FileNotFoundError: [Errno 2] No such file or directory: '/Users/niksharm/.virtualenvs/env1/lib/python3.6/site-packages/digits_sequence_generator/generator/../config/config.yml'
[2019-10-27 14:52:31 +0530] [40565] [ERROR] Exception in worker process
Traceback (most recent call last):
  File "/Users/niksharm/.virtualenvs/env1/lib/python3.6/site-packages/gunicorn/arbiter.py", line 583, in spawn_worker
    worker.init_process()
  File "/Users/niksharm/.virtualenvs/env1/lib/python3.6/site-packages/gunicorn/workers/ggevent.py", line 203, in init_process
    super(GeventWorker, self).init_process()
  File "/Users/niksharm/.virtualenvs/env1/lib/python3.6/site-packages/gunicorn/workers/base.py", line 129, in init_process
    self.load_wsgi()
  File "/Users/niksharm/.virtualenvs/env1/lib/python3.6/site-packages/gunicorn/workers/base.py", line 138, in load_wsgi
    self.wsgi = self.app.wsgi()
  File "/Users/niksharm/.virtualenvs/env1/lib/python3.6/site-packages/gunicorn/app/base.py", line 67, in wsgi
    self.callable = self.load()
  File "/Users/niksharm/.virtualenvs/env1/lib/python3.6/site-packages/gunicorn/app/wsgiapp.py", line 52, in load
    return self.load_wsgiapp()
  File "/Users/niksharm/.virtualenvs/env1/lib/python3.6/site-packages/gunicorn/app/wsgiapp.py", line 41, in load_wsgiapp
    return util.import_app(self.app_uri)
  File "/Users/niksharm/.virtualenvs/env1/lib/python3.6/site-packages/gunicorn/util.py", line 350, in import_app
    __import__(module)
  File "/Users/niksharm/Downloads/sampleproject-master/digits_sequence_generator/api_controller.py", line 3, in <module>
    from digits_sequence_generator import generator
  File "/Users/niksharm/.virtualenvs/env1/lib/python3.6/site-packages/digits_sequence_generator/generator/__init__.py", line 4, in <module>
    from digits_sequence_generator.generator import image_generator
  File "/Users/niksharm/.virtualenvs/env1/lib/python3.6/site-packages/digits_sequence_generator/generator/image_generator.py", line 6, in <module>
    from digits_sequence_generator.data_handler import post_processing
  File "/Users/niksharm/.virtualenvs/env1/lib/python3.6/site-packages/digits_sequence_generator/data_handler/post_processing.py", line 11, in <module>
    config = utility.read_config()
  File "/Users/niksharm/.virtualenvs/env1/lib/python3.6/site-packages/digits_sequence_generator/generator/util.py", line 10, in read_config
    with open(os.path.join(config_folder_path,"config/config.yml"), 'r') as ymlfile:
FileNotFoundError: [Errno 2] No such file or directory: '/Users/niksharm/.virtualenvs/env1/lib/python3.6/site-packages/digits_sequence_generator/generator/../config/config.yml'
[2019-10-27 14:52:31 +0530] [40568] [ERROR] Exception in worker process
Traceback (most recent call last):
  File "/Users/niksharm/.virtualenvs/env1/lib/python3.6/site-packages/gunicorn/arbiter.py", line 583, in spawn_worker
    worker.init_process()
  File "/Users/niksharm/.virtualenvs/env1/lib/python3.6/site-packages/gunicorn/workers/ggevent.py", line 203, in init_process
    super(GeventWorker, self).init_process()
  File "/Users/niksharm/.virtualenvs/env1/lib/python3.6/site-packages/gunicorn/workers/base.py", line 129, in init_process
    self.load_wsgi()
  File "/Users/niksharm/.virtualenvs/env1/lib/python3.6/site-packages/gunicorn/workers/base.py", line 138, in load_wsgi
    self.wsgi = self.app.wsgi()
  File "/Users/niksharm/.virtualenvs/env1/lib/python3.6/site-packages/gunicorn/app/base.py", line 67, in wsgi
    self.callable = self.load()
  File "/Users/niksharm/.virtualenvs/env1/lib/python3.6/site-packages/gunicorn/app/wsgiapp.py", line 52, in load
    return self.load_wsgiapp()
  File "/Users/niksharm/.virtualenvs/env1/lib/python3.6/site-packages/gunicorn/app/wsgiapp.py", line 41, in load_wsgiapp
    return util.import_app(self.app_uri)
  File "/Users/niksharm/.virtualenvs/env1/lib/python3.6/site-packages/gunicorn/util.py", line 350, in import_app
    __import__(module)
  File "/Users/niksharm/Downloads/sampleproject-master/digits_sequence_generator/api_controller.py", line 3, in <module>
    from digits_sequence_generator import generator
  File "/Users/niksharm/.virtualenvs/env1/lib/python3.6/site-packages/digits_sequence_generator/generator/__init__.py", line 4, in <module>
    from digits_sequence_generator.generator import image_generator
  File "/Users/niksharm/.virtualenvs/env1/lib/python3.6/site-packages/digits_sequence_generator/generator/image_generator.py", line 6, in <module>
    from digits_sequence_generator.data_handler import post_processing
  File "/Users/niksharm/.virtualenvs/env1/lib/python3.6/site-packages/digits_sequence_generator/data_handler/post_processing.py", line 11, in <module>
    config = utility.read_config()
  File "/Users/niksharm/.virtualenvs/env1/lib/python3.6/site-packages/digits_sequence_generator/generator/util.py", line 10, in read_config
    with open(os.path.join(config_folder_path,"config/config.yml"), 'r') as ymlfile:
FileNotFoundError: [Errno 2] No such file or directory: '/Users/niksharm/.virtualenvs/env1/lib/python3.6/site-packages/digits_sequence_generator/generator/../config/config.yml'
[2019-10-27 14:52:31 +0530] [40567] [ERROR] Exception in worker process
Traceback (most recent call last):
  File "/Users/niksharm/.virtualenvs/env1/lib/python3.6/site-packages/gunicorn/arbiter.py", line 583, in spawn_worker
    worker.init_process()
  File "/Users/niksharm/.virtualenvs/env1/lib/python3.6/site-packages/gunicorn/workers/ggevent.py", line 203, in init_process
    super(GeventWorker, self).init_process()
  File "/Users/niksharm/.virtualenvs/env1/lib/python3.6/site-packages/gunicorn/workers/base.py", line 129, in init_process
    self.load_wsgi()
  File "/Users/niksharm/.virtualenvs/env1/lib/python3.6/site-packages/gunicorn/workers/base.py", line 138, in load_wsgi
    self.wsgi = self.app.wsgi()
  File "/Users/niksharm/.virtualenvs/env1/lib/python3.6/site-packages/gunicorn/app/base.py", line 67, in wsgi
    self.callable = self.load()
  File "/Users/niksharm/.virtualenvs/env1/lib/python3.6/site-packages/gunicorn/app/wsgiapp.py", line 52, in load
    return self.load_wsgiapp()
  File "/Users/niksharm/.virtualenvs/env1/lib/python3.6/site-packages/gunicorn/app/wsgiapp.py", line 41, in load_wsgiapp
    return util.import_app(self.app_uri)
  File "/Users/niksharm/.virtualenvs/env1/lib/python3.6/site-packages/gunicorn/util.py", line 350, in import_app
    __import__(module)
  File "/Users/niksharm/Downloads/sampleproject-master/digits_sequence_generator/api_controller.py", line 3, in <module>
    from digits_sequence_generator import generator
  File "/Users/niksharm/.virtualenvs/env1/lib/python3.6/site-packages/digits_sequence_generator/generator/__init__.py", line 4, in <module>
    from digits_sequence_generator.generator import image_generator
  File "/Users/niksharm/.virtualenvs/env1/lib/python3.6/site-packages/digits_sequence_generator/generator/image_generator.py", line 6, in <module>
    from digits_sequence_generator.data_handler import post_processing
  File "/Users/niksharm/.virtualenvs/env1/lib/python3.6/site-packages/digits_sequence_generator/data_handler/post_processing.py", line 11, in <module>
    config = utility.read_config()
  File "/Users/niksharm/.virtualenvs/env1/lib/python3.6/site-packages/digits_sequence_generator/generator/util.py", line 10, in read_config
    with open(os.path.join(config_folder_path,"config/config.yml"), 'r') as ymlfile:
FileNotFoundError: [Errno 2] No such file or directory: '/Users/niksharm/.virtualenvs/env1/lib/python3.6/site-packages/digits_sequence_generator/generator/../config/config.yml'
[2019-10-27 14:52:31 +0530] [40566] [INFO] Worker exiting (pid: 40566)
[2019-10-27 14:52:31 +0530] [40568] [INFO] Worker exiting (pid: 40568)
[2019-10-27 14:52:31 +0530] [40565] [INFO] Worker exiting (pid: 40565)
[2019-10-27 14:52:31 +0530] [40567] [INFO] Worker exiting (pid: 40567)
[2019-10-27 15:32:29 +0530] [43789] [DEBUG] Current configuration:
  config: None
  bind: ['localhost:5000']
  backlog: 2048
  workers: 4
  worker_class: gevent
  threads: 1
  worker_connections: 1000
  max_requests: 0
  max_requests_jitter: 0
  timeout: 600
  graceful_timeout: 30
  keepalive: 2
  limit_request_line: 4094
  limit_request_fields: 100
  limit_request_field_size: 8190
  reload: True
  reload_engine: auto
  reload_extra_files: []
  spew: False
  check_config: False
  preload_app: False
  sendfile: None
  reuse_port: False
  chdir: /Users/niksharm/Downloads/digit-sequence-generator/digits_sequence_generator
  daemon: False
  raw_env: []
  pidfile: None
  worker_tmp_dir: None
  user: 1528380487
  group: 1493692218
  umask: 0
  initgroups: False
  tmp_upload_dir: None
  secure_scheme_headers: {'X-FORWARDED-PROTOCOL': 'ssl', 'X-FORWARDED-PROTO': 'https', 'X-FORWARDED-SSL': 'on'}
  forwarded_allow_ips: ['127.0.0.1']
  accesslog: None
  disable_redirect_access_to_syslog: False
  access_log_format: %(h)s %(l)s %(u)s %(t)s "%(r)s" %(s)s %(b)s "%(f)s" "%(a)s"
  errorlog: config/gunicorn-logs.log
  loglevel: DEBUG
  capture_output: False
  logger_class: gunicorn.glogging.Logger
  logconfig: None
  logconfig_dict: {}
  syslog_addr: unix:///var/run/syslog
  syslog: False
  syslog_prefix: None
  syslog_facility: user
  enable_stdio_inheritance: False
  statsd_host: None
  statsd_prefix: 
  proc_name: None
  default_proc_name: api_controller:app
  pythonpath: None
  paste: None
  on_starting: <function OnStarting.on_starting at 0x105c067b8>
  on_reload: <function OnReload.on_reload at 0x105c068c8>
  when_ready: <function WhenReady.when_ready at 0x105c069d8>
  pre_fork: <function Prefork.pre_fork at 0x105c06ae8>
  post_fork: <function Postfork.post_fork at 0x105c06bf8>
  post_worker_init: <function PostWorkerInit.post_worker_init at 0x105c06d08>
  worker_int: <function WorkerInt.worker_int at 0x105c06e18>
  worker_abort: <function WorkerAbort.worker_abort at 0x105c06f28>
  pre_exec: <function PreExec.pre_exec at 0x105c200d0>
  pre_request: <function PreRequest.pre_request at 0x105c201e0>
  post_request: <function PostRequest.post_request at 0x105c20268>
  child_exit: <function ChildExit.child_exit at 0x105c20378>
  worker_exit: <function WorkerExit.worker_exit at 0x105c20488>
  nworkers_changed: <function NumWorkersChanged.nworkers_changed at 0x105c20598>
  on_exit: <function OnExit.on_exit at 0x105c206a8>
  proxy_protocol: False
  proxy_allow_ips: ['127.0.0.1']
  keyfile: None
  certfile: None
  ssl_version: 2
  cert_reqs: 0
  ca_certs: None
  suppress_ragged_eofs: True
  do_handshake_on_connect: False
  ciphers: TLSv1
  raw_paste_global_conf: []
[2019-10-27 15:32:29 +0530] [43789] [INFO] Starting gunicorn 19.9.0
[2019-10-27 15:32:29 +0530] [43789] [DEBUG] Arbiter booted
[2019-10-27 15:32:29 +0530] [43789] [INFO] Listening at: http://127.0.0.1:5000 (43789)
[2019-10-27 15:32:29 +0530] [43789] [INFO] Using worker: gevent
[2019-10-27 15:32:29 +0530] [43792] [INFO] Booting worker with pid: 43792
[2019-10-27 15:32:29 +0530] [43793] [INFO] Booting worker with pid: 43793
[2019-10-27 15:32:29 +0530] [43794] [INFO] Booting worker with pid: 43794
[2019-10-27 15:32:29 +0530] [43795] [INFO] Booting worker with pid: 43795
[2019-10-27 15:32:29 +0530] [43789] [DEBUG] 4 workers
[2019-10-27 15:32:43 +0530] [43802] [DEBUG] Current configuration:
  config: None
  bind: ['localhost:5000']
  backlog: 2048
  workers: 4
  worker_class: gevent
  threads: 1
  worker_connections: 1000
  max_requests: 0
  max_requests_jitter: 0
  timeout: 600
  graceful_timeout: 30
  keepalive: 2
  limit_request_line: 4094
  limit_request_fields: 100
  limit_request_field_size: 8190
  reload: True
  reload_engine: auto
  reload_extra_files: []
  spew: False
  check_config: False
  preload_app: False
  sendfile: None
  reuse_port: False
  chdir: /Users/niksharm/Downloads/digit-sequence-generator/digits_sequence_generator
  daemon: False
  raw_env: []
  pidfile: None
  worker_tmp_dir: None
  user: 1528380487
  group: 1493692218
  umask: 0
  initgroups: False
  tmp_upload_dir: None
  secure_scheme_headers: {'X-FORWARDED-PROTOCOL': 'ssl', 'X-FORWARDED-PROTO': 'https', 'X-FORWARDED-SSL': 'on'}
  forwarded_allow_ips: ['127.0.0.1']
  accesslog: None
  disable_redirect_access_to_syslog: False
  access_log_format: %(h)s %(l)s %(u)s %(t)s "%(r)s" %(s)s %(b)s "%(f)s" "%(a)s"
  errorlog: config/gunicorn-logs.log
  loglevel: DEBUG
  capture_output: False
  logger_class: gunicorn.glogging.Logger
  logconfig: None
  logconfig_dict: {}
  syslog_addr: unix:///var/run/syslog
  syslog: False
  syslog_prefix: None
  syslog_facility: user
  enable_stdio_inheritance: False
  statsd_host: None
  statsd_prefix: 
  proc_name: None
  default_proc_name: api_controller:app
  pythonpath: None
  paste: None
  on_starting: <function OnStarting.on_starting at 0x1037092f0>
  on_reload: <function OnReload.on_reload at 0x103709400>
  when_ready: <function WhenReady.when_ready at 0x103709510>
  pre_fork: <function Prefork.pre_fork at 0x103709620>
  post_fork: <function Postfork.post_fork at 0x103709730>
  post_worker_init: <function PostWorkerInit.post_worker_init at 0x103709840>
  worker_int: <function WorkerInt.worker_int at 0x103709950>
  worker_abort: <function WorkerAbort.worker_abort at 0x103709a60>
  pre_exec: <function PreExec.pre_exec at 0x103709b70>
  pre_request: <function PreRequest.pre_request at 0x103709c80>
  post_request: <function PostRequest.post_request at 0x103709d08>
  child_exit: <function ChildExit.child_exit at 0x103709e18>
  worker_exit: <function WorkerExit.worker_exit at 0x103709f28>
  nworkers_changed: <function NumWorkersChanged.nworkers_changed at 0x1037240d0>
  on_exit: <function OnExit.on_exit at 0x1037241e0>
  proxy_protocol: False
  proxy_allow_ips: ['127.0.0.1']
  keyfile: None
  certfile: None
  ssl_version: 2
  cert_reqs: 0
  ca_certs: None
  suppress_ragged_eofs: True
  do_handshake_on_connect: False
  ciphers: TLSv1
  raw_paste_global_conf: []
[2019-10-27 15:32:43 +0530] [43802] [INFO] Starting gunicorn 19.9.0
[2019-10-27 15:32:43 +0530] [43802] [ERROR] Connection in use: ('localhost', 5000)
[2019-10-27 15:32:43 +0530] [43802] [DEBUG] connection to ('localhost', 5000) failed: [Errno 48] Address already in use
[2019-10-27 15:32:43 +0530] [43802] [ERROR] Retrying in 1 second.
[2019-10-27 15:32:44 +0530] [43802] [ERROR] Connection in use: ('localhost', 5000)
[2019-10-27 15:32:44 +0530] [43802] [DEBUG] connection to ('localhost', 5000) failed: [Errno 48] Address already in use
[2019-10-27 15:32:44 +0530] [43802] [ERROR] Retrying in 1 second.
[2019-10-27 15:32:45 +0530] [43802] [ERROR] Connection in use: ('localhost', 5000)
[2019-10-27 15:32:45 +0530] [43802] [DEBUG] connection to ('localhost', 5000) failed: [Errno 48] Address already in use
[2019-10-27 15:32:45 +0530] [43802] [ERROR] Retrying in 1 second.
[2019-10-27 15:32:46 +0530] [43802] [ERROR] Connection in use: ('localhost', 5000)
[2019-10-27 15:32:46 +0530] [43802] [DEBUG] connection to ('localhost', 5000) failed: [Errno 48] Address already in use
[2019-10-27 15:32:46 +0530] [43802] [ERROR] Retrying in 1 second.
[2019-10-27 15:32:47 +0530] [43802] [ERROR] Connection in use: ('localhost', 5000)
[2019-10-27 15:32:47 +0530] [43802] [DEBUG] connection to ('localhost', 5000) failed: [Errno 48] Address already in use
[2019-10-27 15:32:47 +0530] [43802] [ERROR] Retrying in 1 second.
[2019-10-27 15:32:48 +0530] [43802] [ERROR] Can't connect to ('localhost', 5000)
[2019-10-27 15:56:24 +0530] [43793] [INFO] Worker reloading: /Users/niksharm/Downloads/digit-sequence-generator/digits_sequence_generator/api_controller.py modified
[2019-10-27 15:56:24 +0530] [43792] [INFO] Worker reloading: /Users/niksharm/Downloads/digit-sequence-generator/digits_sequence_generator/api_controller.py modified
[2019-10-27 15:56:24 +0530] [43795] [INFO] Worker reloading: /Users/niksharm/Downloads/digit-sequence-generator/digits_sequence_generator/api_controller.py modified
[2019-10-27 15:56:24 +0530] [43794] [INFO] Worker reloading: /Users/niksharm/Downloads/digit-sequence-generator/digits_sequence_generator/api_controller.py modified
[2019-10-27 15:56:25 +0530] [43792] [INFO] Worker exiting (pid: 43792)
[2019-10-27 15:56:25 +0530] [43793] [INFO] Worker exiting (pid: 43793)
[2019-10-27 15:56:25 +0530] [43794] [INFO] Worker exiting (pid: 43794)
[2019-10-27 15:56:25 +0530] [43795] [INFO] Worker exiting (pid: 43795)
[2019-10-27 15:56:26 +0530] [44577] [INFO] Booting worker with pid: 44577
[2019-10-27 15:56:26 +0530] [43789] [DEBUG] 1 workers
[2019-10-27 15:56:26 +0530] [44578] [INFO] Booting worker with pid: 44578
[2019-10-27 15:56:26 +0530] [44579] [INFO] Booting worker with pid: 44579
[2019-10-27 15:56:26 +0530] [43789] [DEBUG] 4 workers
[2019-10-27 15:56:26 +0530] [44580] [INFO] Booting worker with pid: 44580
[2019-10-27 16:06:47 +0530] [44578] [INFO] Worker reloading: /Users/niksharm/Downloads/digit-sequence-generator/digits_sequence_generator/api_controller.py modified
[2019-10-27 16:06:47 +0530] [44577] [INFO] Worker reloading: /Users/niksharm/Downloads/digit-sequence-generator/digits_sequence_generator/api_controller.py modified
[2019-10-27 16:06:47 +0530] [44579] [INFO] Worker reloading: /Users/niksharm/Downloads/digit-sequence-generator/digits_sequence_generator/api_controller.py modified
[2019-10-27 16:06:47 +0530] [44580] [INFO] Worker reloading: /Users/niksharm/Downloads/digit-sequence-generator/digits_sequence_generator/api_controller.py modified
[2019-10-27 16:06:48 +0530] [44578] [INFO] Worker exiting (pid: 44578)
[2019-10-27 16:06:48 +0530] [44577] [INFO] Worker exiting (pid: 44577)
[2019-10-27 16:06:48 +0530] [44579] [INFO] Worker exiting (pid: 44579)
[2019-10-27 16:06:48 +0530] [44580] [INFO] Worker exiting (pid: 44580)
[2019-10-27 16:06:48 +0530] [44944] [INFO] Booting worker with pid: 44944
[2019-10-27 16:06:48 +0530] [44945] [INFO] Booting worker with pid: 44945
[2019-10-27 16:06:49 +0530] [44946] [INFO] Booting worker with pid: 44946
[2019-10-27 16:06:49 +0530] [43789] [DEBUG] 3 workers
[2019-10-27 16:06:49 +0530] [44947] [INFO] Booting worker with pid: 44947
[2019-10-27 16:06:49 +0530] [43789] [DEBUG] 4 workers
[2019-10-27 16:06:52 +0530] [44945] [INFO] Worker reloading: /Users/niksharm/Downloads/digit-sequence-generator/digits_sequence_generator/api_controller.py modified
[2019-10-27 16:06:52 +0530] [44947] [INFO] Worker reloading: /Users/niksharm/Downloads/digit-sequence-generator/digits_sequence_generator/api_controller.py modified
[2019-10-27 16:06:52 +0530] [44944] [INFO] Worker reloading: /Users/niksharm/Downloads/digit-sequence-generator/digits_sequence_generator/api_controller.py modified
[2019-10-27 16:06:52 +0530] [44946] [INFO] Worker reloading: /Users/niksharm/Downloads/digit-sequence-generator/digits_sequence_generator/api_controller.py modified
[2019-10-27 16:06:53 +0530] [44945] [INFO] Worker exiting (pid: 44945)
[2019-10-27 16:06:53 +0530] [44947] [INFO] Worker exiting (pid: 44947)
[2019-10-27 16:06:53 +0530] [44944] [INFO] Worker exiting (pid: 44944)
[2019-10-27 16:06:53 +0530] [44946] [INFO] Worker exiting (pid: 44946)
[2019-10-27 16:06:53 +0530] [44953] [INFO] Booting worker with pid: 44953
[2019-10-27 16:06:53 +0530] [43789] [DEBUG] 1 workers
[2019-10-27 16:06:53 +0530] [44954] [INFO] Booting worker with pid: 44954
[2019-10-27 16:06:53 +0530] [44955] [INFO] Booting worker with pid: 44955
[2019-10-27 16:06:53 +0530] [44956] [INFO] Booting worker with pid: 44956
[2019-10-27 16:06:53 +0530] [43789] [DEBUG] 4 workers
